2025-01-02 17:19:56,771 ERROR: Exception on /notifications [GET] [in /home/akachi/.cache/pypoetry/virtualenvs/bantiapp-cTIl6A_8-py3.12/lib/python3.12/site-packages/flask/app.py:1457
Traceback (most recent call last):
  File "/home/akachi/.cache/pypoetry/virtualenvs/bantiapp-cTIl6A_8-py3.12/lib/python3.12/site-packages/sqlalchemy/engine/base.py", line 1808, in _execute_context
    self.dialect.do_execute(
  File "/home/akachi/.cache/pypoetry/virtualenvs/bantiapp-cTIl6A_8-py3.12/lib/python3.12/site-packages/sqlalchemy/engine/default.py", line 732, in do_execute
    cursor.execute(statement, parameters)
sqlite3.OperationalError: no such table: user

The above exception was the direct cause of the following exception:

Traceback (most recent call last):
  File "/home/akachi/.cache/pypoetry/virtualenvs/bantiapp-cTIl6A_8-py3.12/lib/python3.12/site-packages/flask/app.py", line 2073, in wsgi_app
    response = self.full_dispatch_request()
               ^^^^^^^^^^^^^^^^^^^^^^^^^^^^
  File "/home/akachi/.cache/pypoetry/virtualenvs/bantiapp-cTIl6A_8-py3.12/lib/python3.12/site-packages/flask/app.py", line 1518, in full_dispatch_request
    rv = self.handle_user_exception(e)
         ^^^^^^^^^^^^^^^^^^^^^^^^^^^^^
  File "/home/akachi/.cache/pypoetry/virtualenvs/bantiapp-cTIl6A_8-py3.12/lib/python3.12/site-packages/flask/app.py", line 1514, in full_dispatch_request
    rv = self.preprocess_request()
         ^^^^^^^^^^^^^^^^^^^^^^^^^
  File "/home/akachi/.cache/pypoetry/virtualenvs/bantiapp-cTIl6A_8-py3.12/lib/python3.12/site-packages/flask/app.py", line 1857, in preprocess_request
    rv = self.ensure_sync(before_func)()
         ^^^^^^^^^^^^^^^^^^^^^^^^^^^^^^^
  File "/home/akachi/Desktop/Webstack-Portfolio-Project/Bantiapp/app/main/routes.py", line 30, in before_request
    if current_user.is_authenticated:
       ^^^^^^^^^^^^^^^^^^^^^^^^^^^^^
  File "/home/akachi/.cache/pypoetry/virtualenvs/bantiapp-cTIl6A_8-py3.12/lib/python3.12/site-packages/werkzeug/local.py", line 436, in __get__
    obj = instance._get_current_object()
          ^^^^^^^^^^^^^^^^^^^^^^^^^^^^^^
  File "/home/akachi/.cache/pypoetry/virtualenvs/bantiapp-cTIl6A_8-py3.12/lib/python3.12/site-packages/werkzeug/local.py", line 565, in _get_current_object
    return self.__local()  # type: ignore
           ^^^^^^^^^^^^^^
  File "/home/akachi/.cache/pypoetry/virtualenvs/bantiapp-cTIl6A_8-py3.12/lib/python3.12/site-packages/flask_login/utils.py", line 26, in <lambda>
    current_user = LocalProxy(lambda: _get_user())
                                      ^^^^^^^^^^^
  File "/home/akachi/.cache/pypoetry/virtualenvs/bantiapp-cTIl6A_8-py3.12/lib/python3.12/site-packages/flask_login/utils.py", line 346, in _get_user
    current_app.login_manager._load_user()
  File "/home/akachi/.cache/pypoetry/virtualenvs/bantiapp-cTIl6A_8-py3.12/lib/python3.12/site-packages/flask_login/login_manager.py", line 318, in _load_user
    user = self._user_callback(user_id)
           ^^^^^^^^^^^^^^^^^^^^^^^^^^^^
  File "/home/akachi/Desktop/Webstack-Portfolio-Project/Bantiapp/app/models/user.py", line 279, in load_user
    return User.query.get(int(id))
           ^^^^^^^^^^^^^^^^^^^^^^^
  File "<string>", line 2, in get
  File "/home/akachi/.cache/pypoetry/virtualenvs/bantiapp-cTIl6A_8-py3.12/lib/python3.12/site-packages/sqlalchemy/util/deprecations.py", line 401, in warned
    return fn(*args, **kwargs)
           ^^^^^^^^^^^^^^^^^^^
  File "/home/akachi/.cache/pypoetry/virtualenvs/bantiapp-cTIl6A_8-py3.12/lib/python3.12/site-packages/sqlalchemy/orm/query.py", line 943, in get
    return self._get_impl(ident, loading.load_on_pk_identity)
           ^^^^^^^^^^^^^^^^^^^^^^^^^^^^^^^^^^^^^^^^^^^^^^^^^^
  File "/home/akachi/.cache/pypoetry/virtualenvs/bantiapp-cTIl6A_8-py3.12/lib/python3.12/site-packages/sqlalchemy/orm/query.py", line 947, in _get_impl
    return self.session._get_impl(
           ^^^^^^^^^^^^^^^^^^^^^^^
  File "/home/akachi/.cache/pypoetry/virtualenvs/bantiapp-cTIl6A_8-py3.12/lib/python3.12/site-packages/sqlalchemy/orm/session.py", line 2892, in _get_impl
    return db_load_fn(
           ^^^^^^^^^^^
  File "/home/akachi/.cache/pypoetry/virtualenvs/bantiapp-cTIl6A_8-py3.12/lib/python3.12/site-packages/sqlalchemy/orm/loading.py", line 530, in load_on_pk_identity
    session.execute(
  File "/home/akachi/.cache/pypoetry/virtualenvs/bantiapp-cTIl6A_8-py3.12/lib/python3.12/site-packages/sqlalchemy/orm/session.py", line 1692, in execute
    result = conn._execute_20(statement, params or {}, execution_options)
             ^^^^^^^^^^^^^^^^^^^^^^^^^^^^^^^^^^^^^^^^^^^^^^^^^^^^^^^^^^^^
  File "/home/akachi/.cache/pypoetry/virtualenvs/bantiapp-cTIl6A_8-py3.12/lib/python3.12/site-packages/sqlalchemy/engine/base.py", line 1620, in _execute_20
    return meth(self, args_10style, kwargs_10style, execution_options)
           ^^^^^^^^^^^^^^^^^^^^^^^^^^^^^^^^^^^^^^^^^^^^^^^^^^^^^^^^^^^
  File "/home/akachi/.cache/pypoetry/virtualenvs/bantiapp-cTIl6A_8-py3.12/lib/python3.12/site-packages/sqlalchemy/sql/elements.py", line 325, in _execute_on_connection
    return connection._execute_clauseelement(
           ^^^^^^^^^^^^^^^^^^^^^^^^^^^^^^^^^^
  File "/home/akachi/.cache/pypoetry/virtualenvs/bantiapp-cTIl6A_8-py3.12/lib/python3.12/site-packages/sqlalchemy/engine/base.py", line 1487, in _execute_clauseelement
    ret = self._execute_context(
          ^^^^^^^^^^^^^^^^^^^^^^
  File "/home/akachi/.cache/pypoetry/virtualenvs/bantiapp-cTIl6A_8-py3.12/lib/python3.12/site-packages/sqlalchemy/engine/base.py", line 1851, in _execute_context
    self._handle_dbapi_exception(
  File "/home/akachi/.cache/pypoetry/virtualenvs/bantiapp-cTIl6A_8-py3.12/lib/python3.12/site-packages/sqlalchemy/engine/base.py", line 2032, in _handle_dbapi_exception
    util.raise_(
  File "/home/akachi/.cache/pypoetry/virtualenvs/bantiapp-cTIl6A_8-py3.12/lib/python3.12/site-packages/sqlalchemy/util/compat.py", line 207, in raise_
    raise exception
  File "/home/akachi/.cache/pypoetry/virtualenvs/bantiapp-cTIl6A_8-py3.12/lib/python3.12/site-packages/sqlalchemy/engine/base.py", line 1808, in _execute_context
    self.dialect.do_execute(
  File "/home/akachi/.cache/pypoetry/virtualenvs/bantiapp-cTIl6A_8-py3.12/lib/python3.12/site-packages/sqlalchemy/engine/default.py", line 732, in do_execute
    cursor.execute(statement, parameters)
sqlalchemy.exc.OperationalError: (sqlite3.OperationalError) no such table: user
[SQL: SELECT user.id AS user_id, user.uid AS user_uid, user.full_name AS user_full_name, user.username AS user_username, user.email AS user_email, user.password_hash AS user_password_hash, user.about_me AS user_about_me, user.last_seen AS user_last_seen, user.member_since AS user_member_since, user.last_message_read_time AS user_last_message_read_time, user.last_notification_checked_time AS user_last_notification_checked_time 
FROM user 
WHERE user.id = ?]
[parameters: (3,)]
(Background on this error at: https://sqlalche.me/e/14/e3q8)
